Workbook
Name data: #REF!
Name data: #REF!
Name data: #REF!
Name data: #REF!
Name data: #REF!
Name data: #REF!
Name data: #REF!
Name data: #REF!
Name data: #REF!
Name data: #REF!
Name data: #REF!
Name data: #REF!
Name data: #REF!
Name data: #REF!
Name data: #REF!
Name data: #REF!
Name data: #REF!
Name data: #REF!
Name Data1: #REF!
Name Data1: #REF!
Name Data1: #REF!
Name Data1: #REF!
Name Data1: #REF!
Name Data1: #REF!
Name Data1: #REF!
Name Data1: #REF!
Name Data1: #REF!
Name Data1: #REF!
Name Data1: #REF!
Name Data1: #REF!
Name Data1: #REF!
Name Data1: #REF!
Name Data1: #REF!
Name Data1: #REF!
Name Data1: #REF!
Name Data1: #REF!
Name test: #REF!
Name test: #REF!
Name test: #REF!
Name test: #REF!
Name test: #REF!
Name test: #REF!
Name test: #REF!
Name test: #REF!
Name test: #REF!
Name test: #REF!
Name test: #REF!
Name test: #REF!
Name test: #REF!
Name test: #REF!
Name test: #REF!
Name test: #REF!
Name test: #REF!
Name test: #REF!
Name test1: #REF!
Name test1: #REF!
Name test1: #REF!
Name test1: #REF!
Name test1: #REF!
Name test1: #REF!

Sheet Index
A1: Victorian Population Health Survey | C1: Change vs 2015
A2: Time series data 20015-17 | C2: 2016 | F2: 2017
A3: Selected risk factors and chronic diseases | C3: M | D3: F | E3: P | F3: M | G3: F | H3: P
A4: 1 | B4: =BMI!A1 -> Proportion (%) of adult population (18+ years), by body mass index a category and sex, Victoria, 2015-17 | C4: ù | D4: ù | E4: ù | F4: ù | G4: ù | H4: ù
A5: 2 | B5: ='Physical activity'!A1 -> Proportion (%) of adult population (18+ years), by compliance with physical activity guidelinesa, by sex, Victoria, 2015-17 | C5: ù | D5: ù | E5: ù | F5: R | G5: ù | H5: R
A6: 3 | B6: ='Fruit & Veg'!A1 -> Proportion (%) of adult population (18+ years), by compliance with fruit and vegetable consumption guidelinesa and sex, Victoria, 2015-17 | C6: ù | D6: Q | E6: ù | F6: ù | G6: ù | H6: ù
A7: 4 | B7: ='Current smoking'!A1 -> Proportion (%) of adult population (18+ years), by smoking status and sex, Victoria, 2015-17 | C7: ù | D7: ù | E7: ù | F7: ù | G7: R | H7: R
A8: 5 | B8: ='Daily & occasional smoking'!A1 -> Proportion (%) of adult population (18+ years), by smoking frequency and sex, Victoria, 2015-17 | C8: ù | D8: ù | E8: ù | F8: ù | G8: ù | H8: ù
A9: 6 | B9: ='Alcohol lifetime risk'!A1 -> Proportion (%) of adult population (18+ years), by lifetime risk of alcohol-related harmb and sex, Victoria, 2015-17 | C9: ù | D9: ù | E9: ù | F9: ù | G9: ù | H9: ù
A10: 7 | B10: ='Alcohol injury risk'!A1 -> Proportion (%) of adult population (18+ years), by risk of alcohol-related injury from a single occasion of drinkinga and sex, Victoria, 2015-17 | C10: ù | D10: ù | E10: ù | F10: ù | G10: ù | H10: ù
A11: 8 | B11: ='Self-reported health'!A1 -> Proportion (%) of adult population (18+ years), by self-reported health status and sex, Victoria, 2015-17 | C11: ù | D11: ù | E11: ù | F11: ù | G11: ù | H11: ù
A12: 9 | B12: ='Life satisfaction'!A1 -> Proportion (%) of adult population (18+ years), by life-satisfaction and sex, Victoria, 2015-17 | C12: ù | D12: ù | E12: ù | F12: ù | G12: ù | H12: ù
A13: 10 | B13: ='Life worthwhile'!A1 -> Proportion (%) of adult population (18+ years), by feeling of life being worthwhile and sex, Victoria, 2015-17 | C13: ù | D13: ù | E13: ù | F13: ù | G13: ù | H13: ù
A14: 11 | B14: ='Psychological distress'!A1 -> Proportion (%) of adult population (18+ years), by level of psychological distressa and sex, Victoria, 2015-17 | C14: ù | D14: ù | E14: R | F14: ù | G14: ù | H14: ù
A15: 12 | B15: ='High & v high psych distress'!A1 -> Proportion (%) of adult population (18+ years), with high or very high levels of psychological distressa, by sex, Victoria, 2015-17 | C15: ù | D15: ù | E15: ù | F15: ù | G15: ù | H15: ù
A16: 13 | B16: ='High blood pressure'!A1 -> Proportion (%) of adult population (18+ years), diagnosed with high blood pressure ever, by sex, Victoria, 2015-17 | C16: ù | D16: ù | E16: ù | F16: ù | G16: ù | H16: ù
A17: 14 | B17: ='Morbidity status'!A1 -> Proportion (%) of adult population (18+ years), diagnosed with chronic diseasea, by sex, Victoria, 2016-17 | C17: ù | D17: R | E17: R | F17: ù | G17: ù | H17: ù
A18: 15 | B18: ='Chronic disease -1'!A1 -> Proportion (%) of adult population (18+ years), ever diagnosed with types and type 2 diabetes, heart disease and stroke, by sex, Victoria, 2015-17 | C18: ù | D18: ù | E18: ù | F18: ù | G18: ù | H18: ù
A19: 16 | B19: ='Chronic disease - 2'!A1 -> Proportion (%) of adult population (18+ years), ever diagnosed with cancer, osteoporosis, anxiety or depression and arthritis, by sex, Victoria, 2015-17 | C19: ù | D19: ù | E19: Q | F19: ù | G19: Q | H19: Q
A20: Local Government Area snapshot
B21: Age-adjusted proportion (%) of adults (18+ years), with selected risk factors, chronic disease and screening tests, by local government area, Victoria, 2017
C23: ù | D23: No change
C24: R | D24: Better outcome
C25: Q | D25: Worse outcome
C26: M | D26: Males
C27: F | D27: Females
C28: P | D28: People

Sheet LGA snapshot
D1: 2017 Victorian Population Health Survey
D2: Proportion (%) of adults (18+ years), with selected risk factors, chronic disease and screening tests, by local government area, Victoria, 2017
D3: Modifiable risk factorsa | CW3: Doctor diagnosed chronic diseasea | EZ3: Screening tests and treatmenta, b
A4: Local Government Area | D4: Obese | F4: OB_LL_2017 | G4: OB_UL_2017 | H4: OB_SE_2017 | I4: OB_RSE_2017 | J4: Overweight | L4: OW_LL_2017 | M4: OW_UL_2017 | N4: OW_SE_2017 | O4: OW_RSE_2017 | P4: Daily consumer of sugar sweetened soft drinks | R4: SSB_LL_2017 | S4: SSB_UL_2017 | T4: SSB_SE_2017 | U4: SSB_RSE_ | V4: Take-away food consumed > 1 day/week | X4: TA_LL_2017 | Y4: TA_UL_2017 | Z4: TA_SE_2017 | AA4: TA_RSE_2017 | AB4: Sedentary (inactive) | AD4: SED_LL_2017 | AE4: SED_UL_2017 | AF4: SED_SE_2017 | AG4: SED_RSE_2017 | AH4: Insufficiently physically active | AJ4: INSUF_LL_2017 | AK4: INSUF_UL_2017 | AL4: INSUF_SE_2017 | AM4: INSUF_RSE_2017 | AN4: Complied with vegetable consumption guidelines | AP4: veg_13_LL_2017 | AQ4: veg_13_UL_2017 | AR4: veg_13_SE_2017 | AS4: veg_13_RSE_2017 | AT4: Complied with fruit consumption guidelines | AV4: frt_13_LL_2017 | AW4: frt_13_UL_2017 | AX4: frt_13_SE_2017 | AY4: frt_13_RSE_2017 | AZ4: Daily smoker | BB4: daily_smoker_LL_2017 | BC4: daily_smoker_UL_2017 | BD4: daily_smoker_SE_2017 | BE4: daily_smoker_RSE_2017 | BF4: Current (i.e. daily or occasional) smoker | BH4: smoker_LL_2017 | BI4: smoker_UL_2017 | BJ4: smoker_SE_2017 | BK4: smoker_RSE_2017 | BL4: Increased lifetime risk of alcohol-related harm | BN4: alc_lt09_LL_2017 | BO4: alc_lt09_UL_2017 | BP4: alc_lt09_SE_2017 | BQ4: alc_lt09_RSE_2017 | BR4: Increased risk of injury from a single occasion of drinking | BT4: alc_so09_LL_2017 | BU4: alc_so09_UL_2017 | BV4: alc_so09_SE_2017 | BW4: alc_so09_RSE_2017 | BX4: Fair or poor self-reported health | BZ4: srh_LL_2017 | CA4: srh_UL_2017 | CB4: srh_SE_2017 | CC4: srh_RSE_2017 | CD4: Low or medium life satisfaction | CF4: sat_cat2_LL_2017 | CG4: sat_cat2_UL_2017 | CH4: sat_cat2_SE_2017 | CI4: sat_cat2_RSE_2017 | CJ4: High, or very high, levels of psychological distress | CL4: k10scr3_LL_2017 | CM4: k10scr3_UL_2017 | CN4: k10scr3_SE_2017 | CO4: k10scr3_RSE_2017 | CP4: Doctor diagnosed hypertension | CR4: highbp_LL_2017 | CS4: highbp_UL_2017 | CT4: highbp_SE_2017 | CU4: highbp_RSE | CW4: Anxiety or depression | CY4: depression_LL_2017 | CZ4: depression_UL_2017 | DA4: depression_SE_2017 | DB4: depression_RSE_2017 | DC4: Arthritis | DE4: arthritis_LL_2017 | DF4: arthritis_UL_2017 | DG4: arthritis_SE_2017 | DH4: arthritis_RSE_2017 | DI4: Asthma (ever diagnosed) | DK4: asthma_LL_2017 | DL4: asthma_UL_2017 | DM4: asthma_SE_2017 | DN4: asthma_RSE_2017 | DO4: Cancer | DQ4: cancer_LL_2017 | DR4: cancer_UL_2017 | DS4: cancer_SE_2017 | DT4: cancer_RSE_2017 | DU4: Type 2 diabetes | DW4: type2_dm_LL_2017 | DX4: type2_dm_UL_2017 | DY4: type2_dm_SE_2017 | DZ4: type2_dm_RSE | EA4: Heart disease | EC4: heart_LL_2017 | ED4: heart_UL_2017 | EE4: heart_SE_2017 | EF4: heart_RSE_2017 | EG4: Osteoporosis | EI4: osteoporosis_LL_2017 | EJ4: osteoporosis_UL_2017 | EK4: osteoporosis_SE_2017 | EL4: osteoporosis_RSE_2017 | EM4: Stroke | EO4: stroke_LL_2017 | EP4: stroke_UL_2017 | EQ4: stroke_SE_2017 | ER4: stroke_RSE_2017 | ES4: Two, or more, chronic diseases | EU4: multimorb_LL_2017 | EV4: multimorb_UL_2017 | EW4: multimorb_SE_2017 | EX4: multimorb_RSE_2017 | EZ4: Had a blood-lipids test in last 2 yearsa | FB4: chol_chk_LL_2017 | FC4: chol_chk_UL_2017 | FD4: chol_chk_SE_2017 | FE4: chol_chk_RSE | FF4: Had a blood-pressure test in last 2 yearsa | FH4: bp_chk_LL_2017 | FI4: bp_chk_UL_2017 | FJ4: bp_chk_SE_2017 | FK4: bp_chk_RSE | FL4: Had a blood-glucose test in last 2 yearsa | FN4: diab_chk_LL_2017 | FO4: diab_chk_UL_2017 | FP4: diab_chk_SE_2017 | FQ4: diab_chk_RSE | FR4: Had a faecal occult blood test (50+ years of age)b | FT4: fobt_LL_2017 | FU4: fobt_UL_2017 | FV4: fobt_SE_2017 | FW4: fobt_RSE | FX4: Had a bowel exam to detect cancer (last 5 years)b | FZ4: bwlexm_LL_2017 | GA4: bwlexm_UL_2017 | GB4: bwlexm_SE_2017 | GC4: bwlexm_RSE | GD4: Had a mammogram to detect cancer in last 2 yearsb | GF4: mgrm2yrs_LL_2017 | GG4: mgrm2yrs_UL_2017 | GH4: mgrm2yrs_SE_2017 | GI4: mgrm2yrs_RSE | GJ4: Sought help for a mental health related problemb | GL4: mh_prob_LL_2017 | GM4: mh_prob_UL_2017 | GN4: mh_prob_SE_2017 | GO4: mh_prob_RSE
A5: Victoria | D5: 19.26897 | E5: =IF(I5>25,"*",IF(I5>50,"**","")) | F5: 18.58293 | G5: 19.97411 | H5: 0.354879 | I5: =H5/D5*100 -> 1.8417123 | J5: 50.80429 | K5: =IF(O5>25,"*",IF(O5>50,"**","")) | L5: 49.90919 | M5: 51.69888 | N5: 0.456592 | O5: =N5/J5*100 -> 0.89872725 | P5: 10.09867 | Q5: =IF(U5>50,"**",IF(U5>25,"*","")) | R5: 9.516874 | S5: 10.71183 | T5: 0.3047296 | U5: =T5/P5*100 -> 3.0175221 | V5: 15.2893 | W5: =IF(AA5>50,"**",IF(AA5>25,"*","")) | X5: 14.59565 | Y5: 16.00974 | Z5: 0.3606931 | AA5: =Z5/V5*100 -> 2.3591211 | AB5: 2.539791 | AC5: =IF(AG5>50,"**",IF(AG5>25,"*","")) | AD5: 2.256574 | AE5: 2.857514 | AF5: 0.1529796 | AG5: =AF5/AB5*100 -> 6.0233145 | AH5: 44.08774 | AI5: =IF(AM5>50,"**",IF(AM5>25,"*","")) | AJ5: 43.18836 | AK5: 44.99101 | AL5: 0.4598989 | AM5: =AL5/AH5*100 -> 1.0431446 | AN5: 5.388293 | AO5: =IF(AS5>50,"**",IF(AS5>25,"*","")) | AP5: 5.0284 | AQ5: 5.77238 | AR5: 0.1896708 | AS5: =AR5/AN5*100 -> 3.5200536 | AT5: 43.19355 | AU5: =IF(AY5>50,"**",IF(AY5>25,"*","")) | AV5: 42.28772 | AW5: 44.10395 | AX5: 0.4633656 | AY5: =AX5/AT5*100 -> 1.0727657 | AZ5: 12.42754 | BA5: =IF(BE5>50,"**",IF(BE5>25,"*","")) | BB5: 11.80477 | BC5: 13.0783 | BD5: 0.3248103 | BE5: =BD5/AZ5*100 -> 2.6136331 | BF5: 16.741 | BG5: =IF(BK5>50,"**",IF(BK5>25,"*","")) | BH5: 16.03742 | BI5: 17.46903 | BJ5: 0.365174 | BK5: =BJ5/BF5*100 -> 2.1813153 | BL5: 59.48907 | BM5: =IF(BQ5>50,"**",IF(BQ5>25,"*","")) | BN5: 58.59407 | BO5: 60.37781 | BP5: 0.4550752 | BQ5: =BP5/BL5*100 -> 0.76497279 | BR5: 42.98549 | BS5: =IF(BW5>50,"**",IF(BW5>25,"*","")) | BT5: 42.10708 | BU5: 43.86834 | BV5: 0.4493391 | BW5: =BV5/BR5*100 -> 1.0453274 | BX5: 20.28965 | BY5: =IF(CC5>50,"**",IF(CC5>25,"*","")) | BZ5: 19.55869 | CA5: 21.04079 | CB5: 0.3780782 | CC5: =CB5/BX5*100 -> 1.8634042 | CD5: 20.45532 | CE5: =IF(CI5>50,"**",IF(CI5>25,"*","")) | CF5: 19.69321 | CG5: 21.23913 | CH5: 0.3943577 | CI5: =CH5/CD5*100 -> 1.927898 | CJ5: 15.43 | CK5: =IF(CO5>50,"**",IF(CO5>25,"*","")) | CL5: 14.75 | CM5: 16.14 | CN5: 0.36 | CO5: =CN5/CJ5*100 -> 2.3331173 | CP5: 25.42567 | CQ5: =IF(CU5>50,"**",IF(CU5>25,"*","")) | CR5: 24.74985 | CS5: 26.11354 | CT5: 0.3478848 | CU5: =CT5/CP5*100 -> 1.3682424 | CW5: 27.36389 | CX5: =IF(DB5>50,"**",IF(DB5>25,"*","")) | CY5: 26.566 | CZ5: 28.17655 | DA5: 0.4108684 | DB5: =DA5/CW5*100 -> 1.5014985 | DC5: 20.54975 | DD5: =IF(DH5>50,"**",IF(DH5>25,"*","")) | DE5: 19.97896 | DF5: 21.13254 | DG5: 0.2942746 | DH5: =DG5/DC5*100 -> 1.4320106 | DI5: 19.9574 | DJ5: =IF(DN5>50,"**",IF(DN5>25,"*","")) | DK5: 19.24135 | DL5: 20.69326 | DM5: 0.3703749 | DN5: =DM5/DI5*100 -> 1.8558274 | DO5: 8.055676 | DP5: =IF(DT5>50,"**",IF(DT5>25,"*","")) | DQ5: 7.650898 | DR5: 8.479904 | DS5: 0.211416 | DT5: =DS5/DO5*100 -> 2.6244352 | DU5: 5.452335 | DV5: =IF(DZ5>50,"**",IF(DZ5>25,"*","")) | DW5: 5.114101 | DX5: 5.81157 | DY5: 0.1778291 | DZ5: =DY5/DU5*100 -> 3.2615219 | EA5: 6.74474 | EB5: =IF(EF5>50,"**",IF(EF5>25,"*","")) | EC5: 6.381202 | ED5: 7.127412 | EE5: 0.1902868 | EF5: =EE5/EA5*100 -> 2.8212622 | EG5: 5.669229 | EH5: =IF(EL5>50,"**",IF(EL5>25,"*","")) | EI5: 5.326293 | EJ5: 6.032838 | EK5: 0.1801491 | EL5: =EK5/EG5*100 -> 3.1776649 | EM5: 2.364184 | EN5: =IF(ER5>50,"**",IF(ER5>25,"*","")) | EO5: 2.142138 | EP5: 2.608632 | EQ5: 0.1188279 | ER5: =EQ5/EM5*100 -> 5.0261697 | ES5: 25.48854 | ET5: =IF(EX5>50,"**",IF(EX5>25,"*","")) | EU5: 24.80298 | EV5: 26.18645 | EW5: 0.3529299 | EX5: =EW5/ES5*100 -> 1.3846611 | EZ5: 56.78789 | FA5: =IF(FE5>50,"**",IF(FE5>25,"*","")) | FB5: 55.95063 | FC5: 57.62128 | FD5: 0.4262163 | FE5: =FD5/EZ5*100 -> 0.75054083 | FF5: 79.5963 | FG5: =IF(FK5>50,"**",IF(FK5>25,"*","")) | FH5: 78.80486 | FI5: 80.36555 | FJ5: 0.3981249 | FK5: =FJ5/FF5*100 -> 0.50018016 | FL5: 50.72365 | FM5: =IF(FQ5>50,"**",IF(FQ5>25,"*","")) | FN5: 49.86354 | FO5: 51.58334 | FP5: 0.438759 | FQ5: =FP5/FL5*100 -> 0.86499887 | FR5: 60.14296 | FS5: =IF(FW5>50,"**",IF(FW5>25,"*","")) | FT5: 58.76671 | FU5: 61.50336 | FV5: 0.6982467 | FW5: =FV5/FR5*100 -> 1.1609783 | FX5: 46.75256 | FY5: =IF(GC5>50,"**",IF(GC5>25,"*","")) | FZ5: 45.59576 | GA5: 47.91285 | GB5: 0.5911798 | GC5: =GB5/FX5*100 -> 1.2644865 | GD5: 79.2266 | GE5: =IF(GI5>50,"**",IF(GI5>25,"*","")) | GF5: 77.66267 | GG5: 80.70823 | GH5: 0.776826 | GI5: =GH5/GD5*100 -> 0.9805116 | GJ5: 17.56419 | GK5: =IF(GO5>50,"**",IF(GO5>25,"*","")) | GL5: 16.87218 | GM5: 18.27835 | GN5: 0.3586909 | GO5: =GN5/GJ5*100 -> 2.0421716
B6: Alpine (S) | D6: 25.61235 | E6: =IF(I6>25,"*",IF(I6>50,"**","")) | F6: 17.59607 | G6: 35.69854 | H6: 4.643873 | I6: =H6/D6*100 -> 18.131382 | J6: 58.81481 | K6: =IF(O6>25,"*",IF(O6>50,"**","")) | L6: 49.52787 | M6: 67.51378 | N6: 4.636899 | O6: =N6/J6*100 -> 7.8838969 | P6: 7.524095 | Q6: =IF(U6>50,"**",IF(U6>25,"*","")) -> * | R6: 4.354448 | S6: 12.69473 | T6: 2.061136 | U6: =T6/P6*100 -> 27.393806 | V6: 7.460271 | W6: =IF(AA6>50,"**",IF(AA6>25,"*","")) -> * | X6: 2.972728 | Y6: 17.50024 | Z6: 3.407647 | AA6: =Z6/V6*100 -> 45.677255 | AB6: 0.8657284 | AC6: =IF(AG6>50,"**",IF(AG6>25,"*","")) -> * | AD6: 0.3340208 | AE6: 2.224934 | AF6: 0.4193522 | AG6: =AF6/AB6*100 -> 48.439233 | AH6: 45.31205 | AI6: =IF(AM6>50,"**",IF(AM6>25,"*","")) | AJ6: 35.91788 | AK6: 55.05243 | AL6: 4.941543 | AM6: =AL6/AH6*100 -> 10.905583 | AN6: 8.152531 | AO6: =IF(AS6>50,"**",IF(AS6>25,"*","")) -> * | AP6: 4.425508 | AQ6: 14.5408 | AR6: 2.485937 | AS6: =AR6/AN6*100 -> 30.492825 | AT6: 40.5504 | AU6: =IF(AY6>50,"**",IF(AY6>25,"*","")) | AV6: 32.80908 | AW6: 48.79189 | AX6: 4.111033 | AY6: =AX6/AT6*100 -> 10.138082 | AZ6: 16.59514 | BA6: =IF(BE6>50,"**",IF(BE6>25,"*","")) | BB6: 10.0593 | BC6: 26.14318 | BD6: 4.067931 | BE6: =BD6/AZ6*100 -> 24.512785 | BF6: 22.05102 | BG6: =IF(BK6>50,"**",IF(BK6>25,"*","")) | BH6: 14.01752 | BI6: 32.92552 | BJ6: 4.833227 | BK6: =BJ6/BF6*100 -> 21.918383 | BL6: 67.43256 | BM6: =IF(BQ6>50,"**",IF(BQ6>25,"*","")) | BN6: 58.98698 | BO6: 74.87963 | BP6: 4.082755 | BQ6: =BP6/BL6*100 -> 6.0545751 | BR6: 53.64262 | BS6: =IF(BW6>50,"**",IF(BW6>25,"*","")) | BT6: 43.86551 | BU6: 63.14748 | BV6: 4.980804 | BW6: =BV6/BR6*100 -> 9.2851617 | BX6: 16.12919 | BY6: =IF(CC6>50,"**",IF(CC6>25,"*","")) | BZ6: 11.77921 | CA6: 21.69063 | CB6: 2.518172 | CC6: =CB6/BX6*100 -> 15.612514 | CD6: 16.51454 | CE6: =IF(CI6>50,"**",IF(CI6>25,"*","")) | CF6: 10.45807 | CG6: 25.09543 | CH6: 3.706324 | CI6: =CH6/CD6*100 -> 22.442793 | CJ6: 15.1 | CK6: =IF(CO6>50,"**",IF(CO6>25,"*","")) -> * | CL6: 8.82 | CM6: 24.64 | CN6: 3.98 | CO6: =CN6/CJ6*100 -> 26.357616 | CP6: 17.24 | CQ6: =IF(CU6>50,"**",IF(CU6>25,"*","")) | CR6: 13.94564 | CS6: 21.12156 | CT6: 1.827845 | CU6: =CT6/CP6*100 -> 10.602349 | CW6: 23.83754 | CX6: =IF(DB6>50,"**",IF(DB6>25,"*","")) | CY6: 17.63122 | CZ6: 31.39582 | DA6: 3.51917 | DB6: =DA6/CW6*100 -> 14.763143 | DC6: 20.66531 | DD6: =IF(DH6>50,"**",IF(DH6>25,"*","")) | DE6: 17.38507 | DF6: 24.38181 | DG6: 1.784651 | DH6: =DG6/DC6*100 -> 8.635975 | DI6: 17.9752 | DJ6: =IF(DN6>50,"**",IF(DN6>25,"*","")) | DK6: 12.90037 | DL6: 24.48519 | DM6: 2.947026 | DN6: =DM6/DI6*100 -> 16.394955 | DO6: 8.416611 | DP6: =IF(DT6>50,"**",IF(DT6>25,"*","")) | DQ6: 6.239715 | DR6: 11.26176 | DS6: 1.269333 | DT6: =DS6/DO6*100 -> 15.081284 | DU6: 4.417968 | DV6: =IF(DZ6>50,"**",IF(DZ6>25,"*","")) | DW6: 2.787194 | DX6: 6.934833 | DY6: 1.02888 | DZ6: =DY6/DU6*100 -> 23.288534 | EA6: 5.552991 | EB6: =IF(EF6>50,"**",IF(EF6>25,"*","")) | EC6: 4.003547 | ED6: 7.654284 | EE6: 0.9189409 | EF6: =EE6/EA6*100 -> 16.548575 | EG6: 5.877363 | EH6: =IF(EL6>50,"**",IF(EL6>25,"*","")) | EI6: 4.066907 | EJ6: 8.423011 | EK6: 1.093038 | EL6: =EK6/EG6*100 -> 18.597422 | EM6: 2.38048 | EN6: =IF(ER6>50,"**",IF(ER6>25,"*","")) -> * | EO6: 1.349114 | EP6: 4.166996 | EQ6: 0.6857067 | ER6: =EQ6/EM6*100 -> 28.805396 | ES6: 22.06043 | ET6: =IF(EX6>50,"**",IF(EX6>25,"*","")) | EU6: 18.51131 | EV6: 26.0723 | EW6: 1.929305 | EX6: =EW6/ES6*100 -> 8.7455458 | EZ6: 47.0362 | FA6: =IF(FE6>50,"**",IF(FE6>25,"*","")) | FB6: 39.24699 | FC6: 54.97251 | FD6: 4.044987 | FE6: =FD6/EZ6*100 -> 8.5997317 | FF6: 69.88124 | FG6: =IF(FK6>50,"**",IF(FK6>25,"*","")) | FH6: 60.08459 | FI6: 78.14792 | FJ6: 4.645997 | FK6: =FJ6/FF6*100 -> 6.6484181 | FL6: 45.41227 | FM6: =IF(FQ6>50,"**",IF(FQ6>25,"*","")) | FN6: 37.88599 | FO6: 53.15423 | FP6: 3.92532 | FQ6: =FP6/FL6*100 -> 8.6437432 | FR6: 66.69169 | FS6: =IF(FW6>50,"**",IF(FW6>25,"*","")) | FT6: 58.74892 | FU6: 73.78747 | FV6: 3.860874 | FW6: =FV6/FR6*100 -> 5.789138 | FX6: 50.36985 | FY6: =IF(GC6>50,"**",IF(GC6>25,"*","")) | FZ6: 43.98312 | GA6: 56.74453 | GB6: 3.273196 | GC6: =GB6/FX6*100 -> 6.4983239 | GD6: 86.21254 | GE6: =IF(GI6>50,"**",IF(GI6>25,"*","")) | GF6: 78.90009 | GG6: 91.27113 | GH6: 3.117682 | GI6: =GH6/GD6*100 -> 3.6162744 | GJ6: 14.49511 | GK6: =IF(GO6>50,"**",IF(GO6>25,"*","")) | GL6: 10.64228 | GM6: 19.43934 | GN6: 2.23247 | GO6: =GN6/GJ6*100 -> 15.401539
B7: Ararat (RC) | D7: 20.80898 | E7: =IF(I7>25,"*",IF(I7>50,"**","")) | F7: 16.1723 | G7: 26.35704 | H7: 2.59777 | I7: =H7/D7*100 -> 12.483889 | J7: 54.63037 | K7: =IF(O7>25,"*",IF(O7>50,"**","")) | L7: 46.19469 | M7: 62.80829 | N7: 4.277389 | O7: =N7/J7*100 -> 7.8296907 | P7: 14.38595 | Q7: =IF(U7>50,"**",IF(U7>25,"*","")) | R7: 8.903312 | S7: 22.41407 | T7: 3.405173 | U7: =T7/P7*100 -> 23.67013 | V7: 13.67098 | W7: =IF(AA7>50,"**",IF(AA7>25,"*","")) | X7: 8.509841 | Y7: 21.23577 | Z7: 3.204061 | AA7: =Z7/V7*100 -> 23.436952 | AB7: 2.795547 | AC7: =IF(AG7>50,"**",IF(AG7>25,"*","")) -> * | AD7: 1.083328 | AE7: 7.021854 | AF7: 1.338504 | AG7: =AF7/AB7*100 -> 47.87986 | AH7: 36.36943 | AI7: =IF(AM7>50,"**",IF(AM7>25,"*","")) | AJ7: 29.89632 | AK7: 43.37686 | AL7: 3.457956 | AM7: =AL7/AH7*100 -> 9.5078642 | AN7: 4.279253 | AO7: =IF(AS7>50,"**",IF(AS7>25,"*","")) -> * | AP7: 2.518526 | AQ7: 7.180254 | AR7: 1.145919 | AS7: =AR7/AN7*100 -> 26.778482 | AT7: 36.54699 | AU7: =IF(AY7>50,"**",IF(AY7>25,"*","")) | AV7: 29.25957 | AW7: 44.50748 | AX7: 3.91753 | AY7: =AX7/AT7*100 -> 10.719159 | AZ7: 17.22465 | BA7: =IF(BE7>50,"**",IF(BE7>25,"*","")) | BB7: 11.27334 | BC7: 25.4177 | BD7: 3.588609 | BE7: =BD7/AZ7*100 -> 20.834148 | BF7: 21.85546 | BG7: =IF(BK7>50,"**",IF(BK7>25,"*","")) | BH7: 15.51848 | BI7: 29.86535 | BJ7: 3.6631 | BK7: =BJ7/BF7*100 -> 16.760572 | BL7: 62.112 | BM7: =IF(BQ7>50,"**",IF(BQ7>25,"*","")) | BN7: 54.29123 | BO7: 69.35007 | BP7: 3.868853 | BQ7: =BP7/BL7*100 -> 6.2288334 | BR7: 48.96995 | BS7: =IF(BW7>50,"**",IF(BW7>25,"*","")) | BT7: 41.24433 | BU7: 56.74509 | BV7: 3.986328 | BW7: =BV7/BR7*100 -> 8.1403555 | BX7: 21.80474 | BY7: =IF(CC7>50,"**",IF(CC7>25,"*","")) | BZ7: 16.23385 | CA7: 28.63389 | CB7: 3.165112 | CC7: =CB7/BX7*100 -> 14.515706 | CD7: 21.63569 | CE7: =IF(CI7>50,"**",IF(CI7>25,"*","")) | CF7: 15.35362 | CG7: 29.58961 | CH7: 3.634 | CI7: =CH7/CD7*100 -> 16.796321 | CJ7: 14.68 | CK7: =IF(CO7>50,"**",IF(CO7>25,"*","")) | CL7: 9.85 | CM7: 21.31 | CN7: 2.9 | CO7: =CN7/CJ7*100 -> 19.754768 | CP7: 34.39413 | CQ7: =IF(CU7>50,"**",IF(CU7>25,"*","")) | CR7: 27.04593 | CS7: 42.57372 | CT7: 3.989187 | CU7: =CT7/CP7*100 -> 11.598453 | CW7: 35.97069 | CX7: =IF(DB7>50,"**",IF(DB7>25,"*","")) | CY7: 28.20475 | CZ7: 44.54813 | DA7: 4.203123 | DB7: =DA7/CW7*100 -> 11.684855 | DC7: 24.14882 | DD7: =IF(DH7>50,"**",IF(DH7>25,"*","")) | DE7: 20.15338 | DF7: 28.65213 | DG7: 2.169965 | DH7: =DG7/DC7*100 -> 8.9858014 | DI7: 33.93419 | DJ7: =IF(DN7>50,"**",IF(DN7>25,"*","")) | DK7: 22.14173 | DL7: 48.1251 | DM7: 6.762122 | DN7: =DM7/DI7*100 -> 19.927165 | DO7: 10.08669 | DP7: =IF(DT7>50,"**",IF(DT7>25,"*","")) | DQ7: 7.366425 | DR7: 13.66332 | DS7: 1.592137 | DT7: =DS7/DO7*100 -> 15.784534 | DU7: 4.443062 | DV7: =IF(DZ7>50,"**",IF(DZ7>25,"*","")) | DW7: 2.905345 | DX7: 6.73817 | DY7: 0.9547266 | DZ7: =DY7/DU7*100 -> 21.488032 | EA7: 7.790197 | EB7: =IF(EF7>50,"**",IF(EF7>25,"*","")) | EC7: 5.161783 | ED7: 11.59341 | EE7: 1.611419 | EF7: =EE7/EA7*100 -> 20.685215 | EG7: 5.302834 | EH7: =IF(EL7>50,"**",IF(EL7>25,"*","")) | EI7: 3.856329 | EJ7: 7.251001 | EK7: 0.8549059 | EL7: =EK7/EG7*100 -> 16.121679 | EM7: 1.722604 | EN7: =IF(ER7>50,"**",IF(ER7>25,"*","")) -> * | EO7: 1.025086 | EP7: 2.88093 | EQ7: 0.4544335 | ER7: =EQ7/EM7*100 -> 26.380613 | ES7: 34.25206 | ET7: =IF(EX7>50,"**",IF(EX7>25,"*","")) | EU7: 27.81072 | EV7: 41.33114 | EW7: 3.467431 | EX7: =EW7/ES7*100 -> 10.123277 | EZ7: 46.74135 | FA7: =IF(FE7>50,"**",IF(FE7>25,"*","")) | FB7: 41.09849 | FC7: 52.46883 | FD7: 2.913089 | FE7: =FD7/EZ7*100 -> 6.2323596 | FF7: 77.39081 | FG7: =IF(FK7>50,"**",IF(FK7>25,"*","")) | FH7: 67.69198 | FI7: 84.83053 | FJ7: 4.381954 | FK7: =FJ7/FF7*100 -> 5.6621116 | FL7: 45.81465 | FM7: =IF(FQ7>50,"**",IF(FQ7>25,"*","")) | FN7: 38.76929 | FO7: 53.03145 | FP7: 3.663038 | FQ7: =FP7/FL7*100 -> 7.9953421 | FR7: 68.6111 | FS7: =IF(FW7>50,"**",IF(FW7>25,"*","")) | FT7: 61.20288 | FU7: 75.17845 | FV7: 3.583504 | FW7: =FV7/FR7*100 -> 5.2229217 | FX7: 54.20967 | FY7: =IF(GC7>50,"**",IF(GC7>25,"*","")) | FZ7: 47.62821 | GA7: 60.64741 | GB7: 3.339932 | GC7: =GB7/FX7*100 -> 6.1611369 | GD7: 73.82013 | GE7: =IF(GI7>50,"**",IF(GI7>25,"*","")) | GF7: 63.95145 | GG7: 81.7578 | GH7: 4.568526 | GI7: =GH7/GD7*100 -> 6.1887266 | GJ7: 17.90312 | GK7: =IF(GO7>50,"**",IF(GO7>25,"*","")) | GL7: 13.32753 | GM7: 23.62146 | GN7: 2.619923 | GO7: =GN7/GJ7*100 -> 14.633891
B8: Ballarat (C) | D8: 23.55693 | E8: =IF(I8>25,"*",IF(I8>50,"**","")) | F8: 18.92226 | G8: 28.92183 | H8: 2.553575 | I8: =H8/D8*100 -> 10.840016 | J8: 51.83049 | K8: =IF(O8>25,"*",IF(O8>50,"**","")) | L8: 45.93428 | M8: 57.67615 | N8: 3.009183 | O8: =N8/J8*100 -> 5.8058162 | P8: 11.15708 | Q8: =IF(U8>50,"**",IF(U8>25,"*","")) | R8: 7.701639 | S8: 15.89585 | T8: 2.06737 | U8: =T8/P8*100 -> 18.529669 | V8: 16.68413 | W8: =IF(AA8>50,"**",IF(AA8>25,"*","")) | X8: 12.42713 | Y8: 22.03251 | Z8: 2.442537 | AA8: =Z8/V8*100 -> 14.639882 | AB8: 2.17171 | AC8: =IF(AG8>50,"**",IF(AG8>25,"*","")) -> * | AD8: 0.8957951 | AE8: 5.170149 | AF8: 0.9739316 | AG8: =AF8/AB8*100 -> 44.846301 | AH8: 49.35948 | AI8: =IF(AM8>50,"**",IF(AM8>25,"*","")) | AJ8: 43.33465 | AK8: 55.40298 | AL8: 3.093677 | AM8: =AL8/AH8*100 -> 6.267645 | AN8: 6.896079 | AO8: =IF(AS8>50,"**",IF(AS8>25,"*","")) | AP8: 4.367997 | AQ8: 10.72328 | AR8: 1.583612 | AS8: =AR8/AN8*100 -> 22.963948 | AT8: 51.25347 | AU8: =IF(AY8>50,"**",IF(AY8>25,"*","")) | AV8: 45.15735 | AW8: 57.31252 | AX8: 3.116152 | AY8: =AX8/AT8*100 -> 6.0798849 | AZ8: 13.48872 | BA8: =IF(BE8>50,"**",IF(BE8>25,"*","")) | BB8: 9.852652 | BC8: 18.19581 | BD8: 2.115219 | BE8: =BD8/AZ8*100 -> 15.681392 | BF8: 15.70825 | BG8: =IF(BK8>50,"**",IF(BK8>25,"*","")) | BH8: 11.78666 | BI8: 20.62949 | BJ8: 2.24746 | BK8: =BJ8/BF8*100 -> 14.307514 | BL8: 62.79705 | BM8: =IF(BQ8>50,"**",IF(BQ8>25,"*","")) | BN8: 56.43764 | BO8: 68.74225 | BP8: 3.153588 | BQ8: =BP8/BL8*100 -> 5.0218728 | BR8: 45.90964 | BS8: =IF(BW8>50,"**",IF(BW8>25,"*","")) | BT8: 39.81546 | BU8: 52.12868 | BV8: 3.156983 | BW8: =BV8/BR8*100 -> 6.8765144 | BX8: 22.4397 | BY8: =IF(CC8>50,"**",IF(CC8>25,"*","")) | BZ8: 17.70601 | CA8: 28.00823 | CB8: 2.62987 | CC8: =CB8/BX8*100 -> 11.71972 | CD8: 20.50742 | CE8: =IF(CI8>50,"**",IF(CI8>25,"*","")) | CF8: 15.8452 | CG8: 26.11573 | CH8: 2.619189 | CI8: =CH8/CD8*100 -> 12.771909 | CJ8: 17.94 | CK8: =IF(CO8>50,"**",IF(CO8>25,"*","")) | CL8: 13.55 | CM8: 23.38 | CN8: 2.5 | CO8: =CN8/CJ8*100 -> 13.93534 | CP8: 23.84817 | CQ8: =IF(CU8>50,"**",IF(CU8>25,"*","")) | CR8: 19.69253 | CS8: 28.56879 | CT8: 2.266372 | CU8: =CT8/CP8*100 -> 9.5033372 | CW8: 36.18317 | CX8: =IF(DB8>50,"**",IF(DB8>25,"*","")) | CY8: 30.50127 | CZ8: 42.27961 | DA8: 3.01729 | DB8: =DA8/CW8*100 -> 8.3389322 | DC8: 21.04778 | DD8: =IF(DH8>50,"**",IF(DH8>25,"*","")) | DE8: 17.99055 | DF8: 24.46952 | DG8: 1.652752 | DH8: =DG8/DC8*100 -> 7.8523816 | DI8: 23.99121 | DJ8: =IF(DN8>50,"**",IF(DN8>25,"*","")) | DK8: 18.93611 | DL8: 29.89808 | DM8: 2.800443 | DN8: =DM8/DI8*100 -> 11.672788 | DO8: 9.755573 | DP8: =IF(DT8>50,"**",IF(DT8>25,"*","")) | DQ8: 7.412131 | DR8: 12.73799 | DS8: 1.34911 | DT8: =DS8/DO8*100 -> 13.829121 | DU8: 4.015668 | DV8: =IF(DZ8>50,"**",IF(DZ8>25,"*","")) | DW8: 2.723597 | DX8: 5.883621 | DY8: 0.7897898 | DZ8: =DY8/DU8*100 -> 19.667707 | EA8: 8.25598 | EB8: =IF(EF8>50,"**",IF(EF8>25,"*","")) | EC8: 6.18522 | ED8: 10.93917 | EE8: 1.202198 | EF8: =EE8/EA8*100 -> 14.561542 | EG8: 5.221105 | EH8: =IF(EL8>50,"**",IF(EL8>25,"*","")) | EI8: 3.600997 | EJ8: 7.513298 | EK8: 0.9807143 | EL8: =EK8/EG8*100 -> 18.783654 | EM8: 2.154139 | EN8: =IF(ER8>50,"**",IF(ER8>25,"*","")) -> * | EO8: 1.145858 | EP8: 4.013619 | EQ8: 0.6898295 | ER8: =EQ8/EM8*100 -> 32.023444 | ES8: 27.38312 | ET8: =IF(EX8>50,"**",IF(EX8>25,"*","")) | EU8: 23.24987 | EV8: 31.94532 | EW8: 2.221627 | EX8: =EW8/ES8*100 -> 8.1131259 | EZ8: 46.84044 | FA8: =IF(FE8>50,"**",IF(FE8>25,"*","")) | FB8: 41.82434 | FC8: 51.92121 | FD8: 2.584457 | FE8: =FD8/EZ8*100 -> 5.5175763 | FF8: 78.89218 | FG8: =IF(FK8>50,"**",IF(FK8>25,"*","")) | FH8: 73.02104 | FI8: 83.76964 | FJ8: 2.742066 | FK8: =FJ8/FF8*100 -> 3.4757133 | FL8: 43.51482 | FM8: =IF(FQ8>50,"**",IF(FQ8>25,"*","")) | FN8: 38.32386 | FO8: 48.85198 | FP8: 2.695508 | FQ8: =FP8/FL8*100 -> 6.1944597 | FR8: 67.96301 | FS8: =IF(FW8>50,"**",IF(FW8>25,"*","")) | FT8: 59.44753 | FU8: 75.42942 | FV8: 4.105294 | FW8: =FV8/FR8*100 -> 6.0404829 | FX8: 48.68154 | FY8: =IF(GC8>50,"**",IF(GC8>25,"*","")) | FZ8: 41.87761 | GA8: 55.53468 | GB8: 3.505717 | GC8: =GB8/FX8*100 -> 7.2013272 | GD8: 74.49493 | GE8: =IF(GI8>50,"**",IF(GI8>25,"*","")) | GF8: 62.34579 | GG8: 83.7461 | GH8: 5.50163 | GI8: =GH8/GD8*100 -> 7.3852408 | GJ8: 21.30979 | GK8: =IF(GO8>50,"**",IF(GO8>25,"*","")) | GL8: 16.78484 | GM8: 26.66372 | GN8: 2.520404 | GO8: =GN8/GJ8*100 -> 11.827446
B9: Banyule (C) | D9: 18.49581 | E9: =IF(I9>25,"*",IF(I9>50,"**","")) | F9: 14.27837 | G9: 23.61578 | H9: 2.378471 | I9: =H9/D9*100 -> 12.859513 | J9: 49.25548 | K9: =IF(O9>25,"*",IF(O9>50,"**","")) | L9: 43.28711 | M9: 55.24515 | N9: 3.065131 | O9: =N9/J9*100 -> 6.2229238 | P9: 7.32531 | Q9: =IF(U9>50,"**",IF(U9>25,"*","")) | R9: 4.802494 | S9: 11.01998 | T9: 1.555343 | U9: =T9/P9*100 -> 21.232453 | V9: 18.19952 | W9: =IF(AA9>50,"**",IF(AA9>25,"*","")) | X9: 13.72904 | Y9: 23.72536 | Z9: 2.545165 | AA9: =Z9/V9*100 -> 13.984792 | AB9: 2.77727 | AC9: =IF(AG9>50,"**",IF(AG9>25,"*","")) -> * | AD9: 1.316464 | AE9: 5.764365 | AF9: 1.048947 | AG9: =AF9/AB9*100 -> 37.768996 | AH9: 40.5342 | AI9: =IF(AM9>50,"**",IF(AM9>25,"*","")) | AJ9: 34.79789 | AK9: 46.54114 | AL9: 3.009007 | AM9: =AL9/AH9*100 -> 7.4233783 | AN9: 6.648588 | AO9: =IF(AS9>50,"**",IF(AS9>25,"*","")) | AP9: 4.490375 | AQ9: 9.73834 | AR9: 1.315146 | AS9: =AR9/AN9*100 -> 19.780832 | AT9: 48.36966 | AU9: =IF(AY9>50,"**",IF(AY9>25,"*","")) | AV9: 42.46829 | AW9: 54.31685 | AX9: 3.036789 | AY9: =AX9/AT9*100 -> 6.278293 | AZ9: 10.48191 | BA9: =IF(BE9>50,"**",IF(BE9>25,"*","")) | BB9: 6.983475 | BC9: 15.44197 | BD9: 2.127657 | BE9: =BD9/AZ9*100 -> 20.298371 | BF9: 13.63934 | BG9: =IF(BK9>50,"**",IF(BK9>25,"*","")) | BH9: 9.758979 | BI9: 18.74217 | BJ9: 2.275972 | BK9: =BJ9/BF9*100 -> 16.686819 | BL9: 63.75273 | BM9: =IF(BQ9>50,"**",IF(BQ9>25,"*","")) | BN9: 58.19396 | BO9: 68.96653 | BP9: 2.757743 | BQ9: =BP9/BL9*100 -> 4.3256861 | BR9: 48.17655 | BS9: =IF(BW9>50,"**",IF(BW9>25,"*","")) | BT9: 42.59929 | BU9: 53.79961 | BV9: 2.869195 | BW9: =BV9/BR9*100 -> 5.9555842 | BX9: 16.27499 | BY9: =IF(CC9>50,"**",IF(CC9>25,"*","")) | BZ9: 12.5774 | CA9: 20.80096 | CB9: 2.092171 | CC9: =CB9/BX9*100 -> 12.855129 | CD9: 17.84407 | CE9: =IF(CI9>50,"**",IF(CI9>25,"*","")) | CF9: 13.73247 | CG9: 22.8605 | CH9: 2.324181 | CI9: =CH9/CD9*100 -> 13.024949 | CJ9: 11.49 | CK9: =IF(CO9>50,"**",IF(CO9>25,"*","")) | CL9: 8.03 | CM9: 16.17 | CN9: 2.05 | CO9: =CN9/CJ9*100 -> 17.841601 | CP9: 21.07545 | CQ9: =IF(CU9>50,"**",IF(CU9>25,"*","")) | CR9: 17.95455 | CS9: 24.57633 | CT9: 1.689194 | CU9: =CT9/CP9*100 -> 8.0149843 | CW9: 28.39732 | CX9: =IF(DB9>50,"**",IF(DB9>25,"*","")) | CY9: 23.34327 | CZ9: 34.05943 | DA9: 2.740695 | DB9: =DA9/CW9*100 -> 9.6512453 | DC9: 16.8723 | DD9: =IF(DH9>50,"**",IF(DH9>25,"*","")) | DE9: 13.96163 | DF9: 20.24699 | DG9: 1.601292 | DH9: =DG9/DC9*100 -> 9.4906563 | DI9: 24.08901 | DJ9: =IF(DN9>50,"**",IF(DN9>25,"*","")) | DK9: 19.29941 | DL9: 29.63084 | DM9: 2.639007 | DN9: =DM9/DI9*100 -> 10.955232 | DO9: 7.186332 | DP9: =IF(DT9>50,"**",IF(DT9>25,"*","")) | DQ9: 5.300678 | DR9: 9.674259 | DS9: 1.104118 | DT9: =DS9/DO9*100 -> 15.364138 | DU9: 4.595943 | DV9: =IF(DZ9>50,"**",IF(DZ9>25,"*","")) | DW9: 3.088185 | DX9: 6.788276 | DY9: 0.9245114 | DZ9: =DY9/DU9*100 -> 20.115815 | EA9: 5.458917 | EB9: =IF(EF9>50,"**",IF(EF9>25,"*","")) | EC9: 3.890657 | ED9: 7.60927 | EE9: 0.9350698 | EF9: =EE9/EA9*100 -> 17.129218 | EG9: 3.465762 | EH9: =IF(EL9>50,"**",IF(EL9>25,"*","")) | EI9: 2.325733 | EJ9: 5.135231 | EK9: 0.7009308 | EL9: =EK9/EG9*100 -> 20.224435 | EM9: 1.754683 | EN9: =IF(ER9>50,"**",IF(ER9>25,"*","")) -> * | EO9: 0.8762975 | EP9: 3.482614 | EQ9: 0.6185146 | ER9: =EQ9/EM9*100 -> 35.249364 | ES9: 24.33578 | ET9: =IF(EX9>50,"**",IF(EX9>25,"*","")) | EU9: 19.81854 | EV9: 29.50379 | EW9: 2.473724 | EX9: =EW9/ES9*100 -> 10.164967 | EZ9: 58.47286 | FA9: =IF(FE9>50,"**",IF(FE9>25,"*","")) | FB9: 53.04412 | FC9: 63.70345 | FD9: 2.729213 | FE9: =FD9/EZ9*100 -> 4.6674868 | FF9: 82.87274 | FG9: =IF(FK9>50,"**",IF(FK9>25,"*","")) | FH9: 77.66792 | FI9: 87.0665 | FJ9: 2.391304 | FK9: =FJ9/FF9*100 -> 2.8855134 | FL9: 47.88426 | FM9: =IF(FQ9>50,"**",IF(FQ9>25,"*","")) | FN9: 42.28634 | FO9: 53.53582 | FP9: 2.881891 | FQ9: =FP9/FL9*100 -> 6.0184516 | FR9: 58.14256 | FS9: =IF(FW9>50,"**",IF(FW9>25,"*","")) | FT9: 49.84761 | FU9: 66.00131 | FV9: 4.155959 | FW9: =FV9/FR9*100 -> 7.1478776 | FX9: 48.91977 | FY9: =IF(GC9>50,"**",IF(GC9>25,"*","")) | FZ9: 42.06873 | GA9: 55.81163 | GB9: 3.528036 | GC9: =GB9/FX9*100 -> 7.2118818 | GD9: 83.15048 | GE9: =IF(GI9>50,"**",IF(GI9>25,"*","")) | GF9: 73.27586 | GG9: 89.88031 | GH9: 4.200264 | GI9: =GH9/GD9*100 -> 5.0514008 | GJ9: 19.37957 | GK9: =IF(GO9>50,"**",IF(GO9>25,"*","")) | GL9: 15.06683 | GM9: 24.56967 | GN9: 2.421949 | GO9: =GN9/GJ9*100 -> 12.497434
B10: Bass Coast (S) | D10: 20.26775 | E10: =IF(I10>25,"*",IF(I10>50,"**","")) | F10: 15.17644 | G10: 26.5328 | H10: 2.89543 | I10: =H10/D10*100 -> 14.285898 | J10: 50.94888 | K10: =IF(O10>25,"*",IF(O10>50,"**","")) | L10: 42.70542 | M10: 59.14107 | N10: 4.231055 | O10: =N10/J10*100 -> 8.3045103 | P10: 8.386481 | Q10: =IF(U10>50,"**",IF(U10>25,"*","")) | R10: 5.290379 | S10: 13.04495 | T10: 1.936307 | U10: =T10/P10*100 -> 23.088432 | V10: 10.24482 | W10: =IF(AA10>50,"**",IF(AA10>25,"*","")) -> * | X10: 5.889111 | Y10: 17.23222 | Z10: 2.819776 | AA10: =Z10/V10*100 -> 27.523919 | AB10: 0.8298157 | AC10: =IF(AG10>50,"**",IF(AG10>25,"*","")) -> * | AD10: 0.3672584 | AE10: 1.864058 | AF10: 0.3441933 | AG10: =AF10/AB10*100 -> 41.478282 | AH10: 44.72665 | AI10: =IF(AM10>50,"**",IF(AM10>25,"*","")) | AJ10: 36.58922 | AK10: 53.15673 | AL10: 4.265198 | AM10: =AL10/AH10*100 -> 9.5361446 | AN10: 7.801793 | AO10: =IF(AS10>50,"**",IF(AS10>25,"*","")) -> * | AP10: 3.744942 | AQ10: 15.5437 | AR10: 2.851536 | AS10: =AR10/AN10*100 -> 36.549752 | AT10: 42.88363 | AU10: =IF(AY10>50,"**",IF(AY10>25,"*","")) | AV10: 34.72994 | AW10: 51.44284 | AX10: 4.302927 | AY10: =AX10/AT10*100 -> 10.033962 | AZ10: 18.18584 | BA10: =IF(BE10>50,"**",IF(BE10>25,"*","")) | BB10: 12.21099 | BC10: 26.21132 | BD10: 3.5586 | BE10: =BD10/AZ10*100 -> 19.567972 | BF10: 23.84661 | BG10: =IF(BK10>50,"**",IF(BK10>25,"*","")) | BH10: 16.84803 | BI10: 32.61217 | BJ10: 4.033381 | BK10: =BJ10/BF10*100 -> 16.913855 | BL10: 73.3525 | BM10: =IF(BQ10>50,"**",IF(BQ10>25,"*","")) | BN10: 67.48755 | BO10: 78.49658 | BP10: 2.814876 | BQ10: =BP10/BL10*100 -> 3.8374643 | BR10: 54.45908 | BS10: =IF(BW10>50,"**",IF(BW10>25,"*","")) | BT10: 46.31364 | BU10: 62.37273 | BV10: 4.132113 | BW10: =BV10/BR10*100 -> 7.5875556 | BX10: 25.04505 | BY10: =IF(CC10>50,"**",IF(CC10>25,"*","")) | BZ10: 18.05824 | CA10: 33.62579 | CB10: 3.986173 | CC10: =CB10/BX10*100 -> 15.916011 | CD10: 23.32632 | CE10: =IF(CI10>50,"**",IF(CI10>25,"*","")) | CF10: 16.24278 | CG10: 32.30743 | CH10: 4.108924 | CI10: =CH10/CD10*100 -> 17.614969 | CJ10: 20.08 | CK10: =IF(CO10>50,"**",IF(CO10>25,"*","")) | CL10: 13.76 | CM10: 28.37 | CN10: 3.72 | CO10: =CN10/CJ10*100 -> 18.525896 | CP10: 31.25945 | CQ10: =IF(CU10>50,"**",IF(CU10>25,"*","")) | CR10: 25.13786 | CS10: 38.11284 | CT10: 3.324605 | CU10: =CT10/CP10*100 -> 10.63552 | CW10: 39.05146 | CX10: =IF(DB10>50,"**",IF(DB10>25,"*","")) | CY10: 30.86423 | CZ10: 47.90561 | DA10: 4.387677 | DB10: =DA10/CW10*100 -> 11.235629 | DC10: 25.70075 | DD10: =IF(DH10>50,"**",IF(DH10>25,"*","")) | DE10: 20.69643 | DF10: 31.43544 | DG10: 2.744838 | DH10: =DG10/DC10*100 -> 10.679992 | DI10: 18.84451 | DJ10: =IF(DN10>50,"**",IF(DN10>25,"*","")) | DK10: 13.06762 | DL10: 26.39968 | DM10: 3.392942 | DN10: =DM10/DI10*100 -> 18.004936 | DO10: 12.20931 | DP10: =IF(DT10>50,"**",IF(DT10>25,"*","")) | DQ10: 9.50095 | DR10: 15.55701 | DS10: 1.537721 | DT10: =DS10/DO10*100 -> 12.594659 | DU10: 5.825546 | DV10: =IF(DZ10>50,"**",IF(DZ10>25,"*","")) | DW10: 3.712478 | DX10: 9.028554 | DY10: 1.323217 | DZ10: =DY10/DU10*100 -> 22.714043 | EA10: 8.861826 | EB10: =IF(EF10>50,"**",IF(EF10>25,"*","")) | EC10: 6.292866 | ED10: 12.3414 | EE10: 1.525171 | EF10: =EE10/EA10*100 -> 17.210573 | EG10: 5.477156 | EH10: =IF(EL10>50,"**",IF(EL10>25,"*","")) | EI10: 3.510456 | EJ10: 8.449199 | EK10: 1.229378 | EL10: =EK10/EG10*100 -> 22.445554 | EM10: 2.919772 | EN10: =IF(ER10>50,"**",IF(ER10>25,"*","")) | EO10: 1.831494 | EP10: 4.624245 | EQ10: 0.690571 | ER10: =EQ10/EM10*100 -> 23.651539 | ES10: 34.61232 | ET10: =IF(EX10>50,"**",IF(EX10>25,"*","")) | EU10: 27.46186 | EV10: 42.53293 | EW10: 3.870388 | EX10: =EW10/ES10*100 -> 11.182111 | EZ10: 54.70432 | FA10: =IF(FE10>50,"**",IF(FE10>25,"*","")) | FB10: 48.36395 | FC10: 60.89563 | FD10: 3.21354 | FE10: =FD10/EZ10*100 -> 5.8743807 | FF10: 85.76977 | FG10: =IF(FK10>50,"**",IF(FK10>25,"*","")) | FH10: 78.50589 | FI10: 90.86451 | FJ10: 3.119153 | FK10: =FJ10/FF10*100 -> 3.6366578 | FL10: 51.05243 | FM10: =IF(FQ10>50,"**",IF(FQ10>25,"*","")) | FN10: 43.96208 | FO10: 58.10068 | FP10: 3.631036 | FQ10: =FP10/FL10*100 -> 7.1123666 | FR10: 57.60737 | FS10: =IF(FW10>50,"**",IF(FW10>25,"*","")) | FT10: 49.66497 | FU10: 65.1753 | FV10: 3.987869 | FW10: =FV10/FR10*100 -> 6.9224979 | FX10: 49.01062 | FY10: =IF(GC10>50,"**",IF(GC10>25,"*","")) | FZ10: 42.99915 | GA10: 55.05084 | GB10: 3.089314 | GC10: =GB10/FX10*100 -> 6.3033563 | GD10: 68.70025 | GE10: =IF(GI10>50,"**",IF(GI10>25,"*","")) | GF10: 59.51522 | GG10: 76.62005 | GH10: 4.397043 | GI10: =GH10/GD10*100 -> 6.4003304 | GJ10: 17.74299 | GK10: =IF(GO10>50,"**",IF(GO10>25,"*","")) | GL10: 13.13298 | GM10: 23.53285 | GN10: 2.646343 | GO10: =GN10/GJ10*100 -> 14.914865
B11: Baw Baw (S) | D11: 23.62602 | E11: =IF(I11>25,"*",IF(I11>50,"**","")) | F11: 18.20281 | G11: 30.07098 | H11: 3.032221 | I11: =H11/D11*100 -> 12.834244 | J11: 55.69085 | K11: =IF(O11>25,"*",IF(O11>50,"**","")) | L11: 48.32022 | M11: 62.81913 | N11: 3.724532 | O11: =N11/J11*100 -> 6.6878706 | P11: 10.32553 | Q11: =IF(U11>50,"**",IF(U11>25,"*","")) | R11: 6.492925 | S11: 16.03254 | T11: 2.389241 | U11: =T11/P11*100 -> 23.139161 | V11: 11.81427 | W11: =IF(AA11>50,"**",IF(AA11>25,"*","")) | X11: 7.609865 | Y11: 17.89175 | Z11: 2.585646 | AA11: =Z11/V11*100 -> 21.885787 | AB11: 1.385759 | AC11: =IF(AG11>50,"**",IF(AG11>25,"*","")) -> * | AD11: 0.7570019 | AE11: 2.523475 | AF11: 0.4259904 | AG11: =AF11/AB11*100 -> 30.740583 | AH11: 44.6954 | AI11: =IF(AM11>50,"**",IF(AM11>25,"*","")) | AJ11: 37.46437 | AK11: 52.15804 | AL11: 3.775331 | AM11: =AL11/AH11*100 -> 8.4467999 | AN11: 6.787799 | AO11: =IF(AS11>50,"**",IF(AS11>25,"*","")) | AP11: 4.180212 | AQ11: 10.838 | AR11: 1.6539 | AS11: =AR11/AN11*100 -> 24.365777 | AT11: 52.09098 | AU11: =IF(AY11>50,"**",IF(AY11>25,"*","")) | AV11: 44.8022 | AW11: 59.29181 | AX11: 3.722417 | AY11: =AX11/AT11*100 -> 7.1459915 | AZ11: 18.33911 | BA11: =IF(BE11>50,"**",IF(BE11>25,"*","")) | BB11: 12.52855 | BC11: 26.0422 | BD11: 3.436468 | BE11: =BD11/AZ11*100 -> 18.738467 | BF11: 23.35388 | BG11: =IF(BK11>50,"**",IF(BK11>25,"*","")) | BH11: 17.01726 | BI11: 31.16391 | BJ11: 3.616149 | BK11: =BJ11/BF11*100 -> 15.484147 | BL11: 59.18872 | BM11: =IF(BQ11>50,"**",IF(BQ11>25,"*","")) | BN11: 51.62007 | BO11: 66.34528 | BP11: 3.782847 | BQ11: =BP11/BL11*100 -> 6.391162 | BR11: 45.05243 | BS11: =IF(BW11>50,"**",IF(BW11>25,"*","")) | BT11: 37.63661 | BU11: 52.69479 | BV11: 3.870444 | BW11: =BV11/BR11*100 -> 8.5909772 | BX11: 22.58537 | BY11: =IF(CC11>50,"**",IF(CC11>25,"*","")) | BZ11: 17.52359 | CA11: 28.60222 | CB11: 2.828593 | CC11: =CB11/BX11*100 -> 12.524006 | CD11: 19.44331 | CE11: =IF(CI11>50,"**",IF(CI11>25,"*","")) | CF11: 14.61852 | CG11: 25.38702 | CH11: 2.744006 | CI11: =CH11/CD11*100 -> 14.112854 | CJ11: 14.21 | CK11: =IF(CO11>50,"**",IF(CO11>25,"*","")) | CL11: 10.14 | CM11: 19.55 | CN11: 2.38 | CO11: =CN11/CJ11*100 -> 16.748768 | CP11: 29.3397 | CQ11: =IF(CU11>50,"**",IF(CU11>25,"*","")) | CR11: 24.51617 | CS11: 34.67629 | CT11: 2.5982 | CU11: =CT11/CP11*100 -> 8.8555779 | CW11: 35.41158 | CX11: =IF(DB11>50,"**",IF(DB11>25,"*","")) | CY11: 28.65741 | CZ11: 42.80255 | DA11: 3.630072 | DB11: =DA11/CW11*100 -> 10.251087 | DC11: 24.40433 | DD11: =IF(DH11>50,"**",IF(DH11>25,"*","")) | DE11: 20.19143 | DF11: 29.1749 | DG11: 2.294119 | DH11: =DG11/DC11*100 -> 9.4004589 | DI11: 20.04824 | DJ11: =IF(DN11>50,"**",IF(DN11>25,"*","")) | DK11: 14.48671 | DL11: 27.06903 | DM11: 3.207025 | DN11: =DM11/DI11*100 -> 15.996541 | DO11: 9.830603 | DP11: =IF(DT11>50,"**",IF(DT11>25,"*","")) | DQ11: 7.198033 | DR11: 13.28813 | DS11: 1.539766 | DT11: =DS11/DO11*100 -> 15.662986 | DU11: 5.660679 | DV11: =IF(DZ11>50,"**",IF(DZ11>25,"*","")) | DW11: 3.978416 | DX11: 7.995052 | DY11: 1.009002 | DZ11: =DY11/DU11*100 -> 17.824752 | EA11: 5.270344 | EB11: =IF(EF11>50,"**",IF(EF11>25,"*","")) | EC11: 3.919646 | ED11: 7.052326 | EE11: 0.7902711 | EF11: =EE11/EA11*100 -> 14.994678 | EG11: 5.77646 | EH11: =IF(EL11>50,"**",IF(EL11>25,"*","")) | EI11: 4.160448 | EJ11: 7.967981 | EK11: 0.9585065 | EL11: =EK11/EG11*100 -> 16.59332 | EM11: 2.645921 | EN11: =IF(ER11>50,"**",IF(ER11>25,"*","")) | EO11: 1.637734 | EP11: 4.247943 | EQ11: 0.6439774 | ER11: =EQ11/EM11*100 -> 24.338497 | ES11: 27.08606 | ET11: =IF(EX11>50,"**",IF(EX11>25,"*","")) | EU11: 22.34059 | EV11: 32.41875 | EW11: 2.576127 | EX11: =EW11/ES11*100 -> 9.510896 | EZ11: 50.19528 | FA11: =IF(FE11>50,"**",IF(FE11>25,"*","")) | FB11: 44.06623 | FC11: 56.31846 | FD11: 3.141295 | FE11: =FD11/EZ11*100 -> 6.2581482 | FF11: 76.82858 | FG11: =IF(FK11>50,"**",IF(FK11>25,"*","")) | FH11: 68.63318 | FI11: 83.4006 | FJ11: 3.775029 | FK11: =FJ11/FF11*100 -> 4.9135738 | FL11: 48.71944 | FM11: =IF(FQ11>50,"**",IF(FQ11>25,"*","")) | FN11: 42.84271 | FO11: 54.63179 | FP11: 3.021404 | FQ11: =FP11/FL11*100 -> 6.2016394 | FR11: 58.30151 | FS11: =IF(FW11>50,"**",IF(FW11>25,"*","")) | FT11: 50.20553 | FU11: 65.9733 | FV11: 4.054972 | FW11: =FV11/FR11*100 -> 6.9551749 | FX11: 46.52374 | FY11: =IF(GC11>50,"**",IF(GC11>25,"*","")) | FZ11: 40.08813 | GA11: 53.07721 | GB11: 3.332162 | GC11: =GB11/FX11*100 -> 7.1622832 | GD11: 72.83914 | GE11: =IF(GI11>50,"**",IF(GI11>25,"*","")) | GF11: 62.11927 | GG11: 81.43215 | GH11: 4.964161 | GI11: =GH11/GD11*100 -> 6.8152383 | GJ11: 19.85664 | GK11: =IF(GO11>50,"**",IF(GO11>25,"*","")) | GL11: 15.43853 | GM11: 25.16285 | GN11: 2.47904 | GO11: =GN11/GJ11*100 -> 12.48469
B12: Bayside (C) | D12: 10.57602 | E12: =IF(I12>25,"*",IF(I12>50,"**","")) | F12: 6.74803 | G12: 16.19834 | H12: 2.370389 | I12: =H12/D12*100 -> 22.412864 | J12: 43.20269 | K12: =IF(O12>25,"*",IF(O12>50,"**","")) | L12: 36.45567 | M12: 50.21171 | N12: 3.531085 | O12: =N12/J12*100 -> 8.1732989 | P12: 6.637413 | Q12: =IF(U12>50,"**",IF(U12>25,"*","")) -> * | R12: 3.976193 | S12: 10.87798 | T12: 1.708858 | U12: =T12/P12*100 -> 25.745844 | V12: 14.23768 | W12: =IF(AA12>50,"**",IF(AA12>25,"*","")) | X12: 8.741662 | Y12: 22.34312 | Z12: 3.425789 | AA12: =Z12/V12*100 -> 24.061427 | AB12: 0.7877527 | AC12: =IF(AG12>50,"**",IF(AG12>25,"*","")) -> ** | AD12: 0.2449733 | AE12: 2.502976 | AF12: 0.4679196 | AG12: =AF12/AB12*100 -> 59.399301 | AH12: 34.48299 | AI12: =IF(AM12>50,"**",IF(AM12>25,"*","")) | AJ12: 27.70619 | AK12: 41.9554 | AL12: 3.656638 | AM12: =AL12/AH12*100 -> 10.604179 | AN12: 6.6839 | AO12: =IF(AS12>50,"**",IF(AS12>25,"*","")) -> * | AP12: 3.497501 | AQ12: 12.40024 | AR12: 2.167784 | AS12: =AR12/AN12*100 -> 32.432921 | AT12: 47.98834 | AU12: =IF(AY12>50,"**",IF(AY12>25,"*","")) | AV12: 40.66492 | AW12: 55.39924 | AX12: 3.786204 | AY12: =AX12/AT12*100 -> 7.8898416 | AZ12: 3.145213 | BA12: =IF(BE12>50,"**",IF(BE12>25,"*","")) -> * | BB12: 1.673262 | BC12: 5.83518 | BD12: 1.004309 | BE12: =BD12/AZ12*100 -> 31.931351 | BF12: 9.759404 | BG12: =IF(BK12>50,"**",IF(BK12>25,"*","")) -> * | BH12: 5.410391 | BI12: 16.97684 | BJ12: 2.862109 | BK12: =BJ12/BF12*100 -> 29.326678 | BL12: 77.68785 | BM12: =IF(BQ12>50,"**",IF(BQ12>25,"*","")) | BN12: 71.84286 | BO12: 82.61315 | BP12: 2.749373 | BQ12: =BP12/BL12*100 -> 3.539 | BR12: 60.02416 | BS12: =IF(BW12>50,"**",IF(BW12>25,"*","")) | BT12: 53.56256 | BU12: 66.15478 | BV12: 3.228608 | BW12: =BV12/BR12*100 -> 5.3788475 | BX12: 11.59556 | BY12: =IF(CC12>50,"**",IF(CC12>25,"*","")) | BZ12: 8.395202 | CA12: 15.80543 | CB12: 1.875079 | CC12: =CB12/BX12*100 -> 16.170664 | CD12: 11.17453 | CE12: =IF(CI12>50,"**",IF(CI12>25,"*","")) | CF12: 7.777364 | CG12: 15.80134 | CH12: 2.025401 | CI12: =CH12/CD12*100 -> 18.125156 | CJ12: 10.22 | CK12: =IF(CO12>50,"**",IF(CO12>25,"*","")) | CL12: 6.8 | CM12: 15.08 | CN12: 2.08 | CO12: =CN12/CJ12*100 -> 20.35225 | CP12: 18.68131 | CQ12: =IF(CU12>50,"**",IF(CU12>25,"*","")) | CR12: 15.85538 | CS12: 21.87994 | CT12: 1.535975 | CU12: =CT12/CP12*100 -> 8.2219876 | CW12: 23.00917 | CX12: =IF(DB12>50,"**",IF(DB12>25,"*","")) | CY12: 16.33818 | CZ12: 31.38224 | DA12: 3.845561 | DB12: =DA12/CW12*100 -> 16.713167 | DC12: 17.86619 | DD12: =IF(DH12>50,"**",IF(DH12>25,"*","")) | DE12: 14.59194 | DF12: 21.68856 | DG12: 1.80827 | DH12: =DG12/DC12*100 -> 10.121184 | DI12: 31.3924 | DJ12: =IF(DN12>50,"**",IF(DN12>25,"*","")) | DK12: 22.35905 | DL12: 42.09654 | DM12: 5.087898 | DN12: =DM12/DI12*100 -> 16.20742 | DO12: 7.14091 | DP12: =IF(DT12>50,"**",IF(DT12>25,"*","")) | DQ12: 5.16715 | DR12: 9.790773 | DS12: 1.165651 | DT12: =DS12/DO12*100 -> 16.323564 | DU12: 3.045892 | DV12: =IF(DZ12>50,"**",IF(DZ12>25,"*","")) | DW12: 2.078577 | DX12: 4.442944 | DY12: 0.5906698 | DZ12: =DY12/DU12*100 -> 19.392342 | EA12: 5.918472 | EB12: =IF(EF12>50,"**",IF(EF12>25,"*","")) | EC12: 4.353329 | ED12: 7.999266 | EE12: 0.9194072 | EF12: =EE12/EA12*100 -> 15.534537 | EG12: 4.665183 | EH12: =IF(EL12>50,"**",IF(EL12>25,"*","")) | EI12: 3.146345 | EJ12: 6.865242 | EK12: 0.9296377 | EL12: =EK12/EG12*100 -> 19.927143 | EM12: 0.8543427 | EN12: =IF(ER12>50,"**",IF(ER12>25,"*","")) -> * | EO12: 0.3843908 | EP12: 1.887963 | EQ12: 0.347196 | ER12: =EQ12/EM12*100 -> 40.638961 | ES12: 24.7468 | ET12: =IF(EX12>50,"**",IF(EX12>25,"*","")) | EU12: 18.17029 | EV12: 32.75092 | EW12: 3.731042 | EX12: =EW12/ES12*100 -> 15.076867 | EZ12: 55.41685 | FA12: =IF(FE12>50,"**",IF(FE12>25,"*","")) | FB12: 48.51193 | FC12: 62.11885 | FD12: 3.49249 | FE12: =FD12/EZ12*100 -> 6.3022167 | FF12: 79.63776 | FG12: =IF(FK12>50,"**",IF(FK12>25,"*","")) | FH12: 72.83332 | FI12: 85.08687 | FJ12: 3.124213 | FK12: =FJ12/FF12*100 -> 3.9230297 | FL12: 43.36595 | FM12: =IF(FQ12>50,"**",IF(FQ12>25,"*","")) | FN12: 36.74678 | FO12: 50.23059 | FP12: 3.460372 | FQ12: =FP12/FL12*100 -> 7.9794678 | FR12: 58.86659 | FS12: =IF(FW12>50,"**",IF(FW12>25,"*","")) | FT12: 50.4254 | FU12: 66.81632 | FV12: 4.217845 | FW12: =FV12/FR12*100 -> 7.1650914 | FX12: 48.92033 | FY12: =IF(GC12>50,"**",IF(GC12>25,"*","")) | FZ12: 42.24929 | GA12: 55.63005 | GB12: 3.433925 | GC12: =GB12/FX12*100 -> 7.0194232 | GD12: 78.3952 | GE12: =IF(GI12>50,"**",IF(GI12>25,"*","")) | GF12: 68.62864 | GG12: 85.75246 | GH12: 4.37232 | GI12: =GH12/GD12*100 -> 5.5772802 | GJ12: 16.20185 | GK12: =IF(GO12>50,"**",IF(GO12>25,"*","")) | GL12: 11.12835 | GM12: 22.99004 | GN12: 3.009102 | GO12: =GN12/GJ12*100 -> 18.572583
B13: Benalla (RC) | D13: 31.00831 | E13: =IF(I13>25,"*",IF(I13>50,"**","")) | F13: 21.07001 | G13: 43.076 | H13: 5.686328 | I13: =H13/D13*100 -> 18.338078 | J13: 61.31022 | K13: =IF(O13>25,"*",IF(O13>50,"**","")) | L13: 50.31832 | M13: 71.25927 | N13: 5.417422 | O13: =N13/J13*100 -> 8.8360831 | P13: 19.27231 | Q13: =IF(U13>50,"**",IF(U13>25,"*","")) | R13: 12.89837 | S13: 27.79105 | T13: 3.790728 | U13: =T13/P13*100 -> 19.669298 | V13: 13.95528 | W13: =IF(AA13>50,"**",IF(AA13>25,"*","")) -> * | X13: 7.890436 | Y13: 23.49281 | Z13: 3.910539 | AA13: =Z13/V13*100 -> 28.021931 | AB13: 4.016589 | AC13: =IF(AG13>50,"**",IF(AG13>25,"*","")) -> * | AD13: 2.018117 | AE13: 7.835813 | AF13: 1.394311 | AG13: =AF13/AB13*100 -> 34.713808 | AH13: 53.97627 | AI13: =IF(AM13>50,"**",IF(AM13>25,"*","")) | AJ13: 46.73505 | AK13: 61.05343 | AL13: 3.677693 | AM13: =AL13/AH13*100 -> 6.8135368 | AN13: 7.680507 | AO13: =IF(AS13>50,"**",IF(AS13>25,"*","")) -> * | AP13: 4.618576 | AQ13: 12.50622 | AR13: 1.957941 | AS13: =AR13/AN13*100 -> 25.492341 | AT13: 38.0843 | AU13: =IF(AY13>50,"**",IF(AY13>25,"*","")) | AV13: 29.59345 | AW13: 47.37216 | AX13: 4.580742 | AY13: =AX13/AT13*100 -> 12.027901 | AZ13: 14.41722 | BA13: =IF(BE13>50,"**",IF(BE13>25,"*","")) | BB13: 8.966906 | BC13: 22.36643 | BD13: 3.378101 | BE13: =BD13/AZ13*100 -> 23.431015 | BF13: 17.80689 | BG13: =IF(BK13>50,"**",IF(BK13>25,"*","")) | BH13: 11.37106 | BI13: 26.78448 | BJ13: 3.91209 | BK13: =BJ13/BF13*100 -> 21.96953 | BL13: 59.55327 | BM13: =IF(BQ13>50,"**",IF(BQ13>25,"*","")) | BN13: 49.74207 | BO13: 68.65604 | BP13: 4.881319 | BQ13: =BP13/BL13*100 -> 8.1965591 | BR13: 46.59712 | BS13: =IF(BW13>50,"**",IF(BW13>25,"*","")) | BT13: 37.30932 | BU13: 56.127 | BV13: 4.857969 | BW13: =BV13/BR13*100 -> 10.425471 | BX13: 20.61535 | BY13: =IF(CC13>50,"**",IF(CC13>25,"*","")) | BZ13: 15.02601 | CA13: 27.60828 | CB13: 3.208678 | CC13: =CB13/BX13*100 -> 15.564509 | CD13: 17.36541 | CE13: =IF(CI13>50,"**",IF(CI13>25,"*","")) | CF13: 11.80876 | CG13: 24.80147 | CH13: 3.29981 | CI13: =CH13/CD13*100 -> 19.0022 | CJ13: 19.29 | CK13: =IF(CO13>50,"**",IF(CO13>25,"*","")) | CL13: 12.51 | CM13: 28.53 | CN13: 4.07 | CO13: =CN13/CJ13*100 -> 21.099015 | CP13: 34.91544 | CQ13: =IF(CU13>50,"**",IF(CU13>25,"*","")) | CR13: 24.72885 | CS13: 46.69506 | CT13: 5.685303 | CU13: =CT13/CP13*100 -> 16.283063 | CW13: 37.15099 | CX13: =IF(DB13>50,"**",IF(DB13>25,"*","")) | CY13: 28.14406 | CZ13: 47.14903 | DA13: 4.902997 | DB13: =DA13/CW13*100 -> 13.197487 | DC13: 19.80367 | DD13: =IF(DH13>50,"**",IF(DH13>25,"*","")) | DE13: 16.39355 | DF13: 23.72189 | DG13: 1.868694 | DH13: =DG13/DC13*100 -> 9.4360995 | DI13: 30.6156 | DJ13: =IF(DN13>50,"**",IF(DN13>25,"*","")) | DK13: 25.33027 | DL13: 36.46518 | DM13: 2.849497 | DN13: =DM13/DI13*100 -> 9.3073368 | DO13: 10.22623 | DP13: =IF(DT13>50,"**",IF(DT13>25,"*","")) | DQ13: 7.567493 | DR13: 13.68082 | DS13: 1.546977 | DT13: =DS13/DO13*100 -> 15.12754 | DU13: 4.903474 | DV13: =IF(DZ13>50,"**",IF(DZ13>25,"*","")) | DW13: 3.438366 | DX13: 6.947952 | DY13: 0.8808136 | DZ13: =DY13/DU13*100 -> 17.963052 | EA13: 4.355389 | EB13: =IF(EF13>50,"**",IF(EF13>25,"*","")) | EC13: 3.260099 | ED13: 5.796614 | EE13: 0.6398121 | EF13: =EE13/EA13*100 -> 14.690125 | EG13: 5.774596 | EH13: =IF(EL13>50,"**",IF(EL13>25,"*","")) | EI13: 4.399183 | EJ13: 7.546091 | EK13: 0.7954494 | EL13: =EK13/EG13*100 -> 13.774979 | EM13: 2.279398 | EN13: =IF(ER13>50,"**",IF(ER13>25,"*","")) -> * | EO13: 1.135824 | EP13: 4.521688 | EQ13: 0.804805 | ER13: =EQ13/EM13*100 -> 35.307787 | ES13: 30.73083 | ET13: =IF(EX13>50,"**",IF(EX13>25,"*","")) | EU13: 24.24122 | EV13: 38.0844 | EW13: 3.548851 | EX13: =EW13/ES13*100 -> 11.548178 | EZ13: 61.56902 | FA13: =IF(FE13>50,"**",IF(FE13>25,"*","")) | FB13: 50.25955 | FC13: 71.7523 | FD13: 5.56415 | FE13: =FD13/EZ13*100 -> 9.0372561 | FF13: 88.53976 | FG13: =IF(FK13>50,"**",IF(FK13>25,"*","")) | FH13: 81.2838 | FI13: 93.21744 | FJ13: 2.981941 | FK13: =FJ13/FF13*100 -> 3.3679118 | FL13: 60.9686 | FM13: =IF(FQ13>50,"**",IF(FQ13>25,"*","")) | FN13: 50.08606 | FO13: 70.85893 | FP13: 5.373025 | FQ13: =FP13/FL13*100 -> 8.8127741 | FR13: 70.21308 | FS13: =IF(FW13>50,"**",IF(FW13>25,"*","")) | FT13: 62.70503 | FU13: 76.76961 | FV13: 3.605173 | FW13: =FV13/FR13*100 -> 5.1346174 | FX13: 49.15592 | FY13: =IF(GC13>50,"**",IF(GC13>25,"*","")) | FZ13: 42.47235 | GA13: 55.8698 | GB13: 3.438264 | GC13: =GB13/FX13*100 -> 6.9946082 | GD13: 85.98594 | GE13: =IF(GI13>50,"**",IF(GI13>25,"*","")) | GF13: 76.95188 | GG13: 91.85382 | GH13: 3.740802 | GI13: =GH13/GD13*100 -> 4.350481 | GJ13: 18.50927 | GK13: =IF(GO13>50,"**",IF(GO13>25,"*","")) | GL13: 13.67086 | GM13: 24.57269 | GN13: 2.775622 | GO13: =GN13/GJ13*100 -> 14.995848
B14: Boroondara (C) | D14: 10.53356 | E14: =IF(I14>25,"*",IF(I14>50,"**","")) | F14: 7.676164 | G14: 14.28996 | H14: 1.672658 | I14: =H14/D14*100 -> 15.879323 | J14: 38.01874 | K14: =IF(O14>25,"*",IF(O14>50,"**","")) | L14: 33.21536 | M14: 43.0688 | N14: 2.521214 | O14: =N14/J14*100 -> 6.6315033 | P14: 4.629727 | Q14: =IF(U14>50,"**",IF(U14>25,"*","")) -> * | R14: 2.533127 | S14: 8.31361 | T14: 1.407466 | U14: =T14/P14*100 -> 30.400626 | V14: 12.75485 | W14: =IF(AA14>50,"**",IF(AA14>25,"*","")) | X14: 9.559766 | Y14: 16.81921 | Z14: 1.841284 | AA14: =Z14/V14*100 -> 14.435952 | AB14: 1.954563 | AC14: =IF(AG14>50,"**",IF(AG14>25,"*","")) -> ** | AD14: 0.6723058 | AE14: 5.545863 | AF14: 1.056132 | AG14: =AF14/AB14*100 -> 54.034175 | AH14: 38.51205 | AI14: =IF(AM14>50,"**",IF(AM14>25,"*","")) | AJ14: 33.37054 | AK14: 43.92352 | AL14: 2.701475 | AM14: =AL14/AH14*100 -> 7.0146227 | AN14: 7.988338 | AO14: =IF(AS14>50,"**",IF(AS14>25,"*","")) | AP14: 5.428474 | AQ14: 11.60718 | AR14: 1.551637 | AS14: =AR14/AN14*100 -> 19.423778 | AT14: 47.82057 | AU14: =IF(AY14>50,"**",IF(AY14>25,"*","")) | AV14: 42.57271 | AW14: 53.11698 | AX14: 2.699834 | AY14: =AX14/AT14*100 -> 5.6457587 | AZ14: 4.818616 | BA14: =IF(BE14>50,"**",IF(BE14>25,"*","")) -> * | BB14: 2.790045 | BC14: 8.197732 | BD14: 1.327976 | BE14: =BD14/AZ14*100 -> 27.559283 | BF14: 9.92287 | BG14: =IF(BK14>50,"**",IF(BK14>25,"*","")) | BH14: 6.91337 | BI14: 14.04479 | BJ14: 1.797873 | BK14: =BJ14/BF14*100 -> 18.118478 | BL14: 66.22992 | BM14: =IF(BQ14>50,"**",IF(BQ14>25,"*","")) | BN14: 60.96918 | BO14: 71.1175 | BP14: 2.596456 | BQ14: =BP14/BL14*100 -> 3.9203671 | BR14: 44.99023 | BS14: =IF(BW14>50,"**",IF(BW14>25,"*","")) | BT14: 39.76808 | BU14: 50.32517 | BV14: 2.703056 | BW14: =BV14/BR14*100 -> 6.0080955 | BX14: 14.90785 | BY14: =IF(CC14>50,"**",IF(CC14>25,"*","")) | BZ14: 11.35451 | CA14: 19.3307 | CB14: 2.026932 | CC14: =CB14/BX14*100 -> 13.596407 | CD14: 17.37798 | CE14: =IF(CI14>50,"**",IF(CI14>25,"*","")) | CF14: 13.32475 | CG14: 22.34627 | CH14: 2.296309 | CI14: =CH14/CD14*100 -> 13.213901 | CJ14: 8.85 | CK14: =IF(CO14>50,"**",IF(CO14>25,"*","")) | CL14: 5.99 | CM14: 12.9 | CN14: 1.74 | CO14: =CN14/CJ14*100 -> 19.661017 | CP14: 18.60294 | CQ14: =IF(CU14>50,"**",IF(CU14>25,"*","")) | CR14: 15.02058 | CS14: 22.81035 | CT14: 1.985208 | CU14: =CT14/CP14*100 -> 10.671475 | CW14: 22.17623 | CX14: =IF(DB14>50,"**",IF(DB14>25,"*","")) | CY14: 17.97823 | CZ14: 27.03142 | DA14: 2.310443 | DB14: =DA14/CW14*100 -> 10.418556 | DC14: 16.63747 | DD14: =IF(DH14>50,"**",IF(DH14>25,"*","")) | DE14: 13.26446 | DF14: 20.66384 | DG14: 1.883895 | DH14: =DG14/DC14*100 -> 11.323206 | DI14: 15.93571 | DJ14: =IF(DN14>50,"**",IF(DN14>25,"*","")) | DK14: 12.59658 | DL14: 19.95786 | DM14: 1.873318 | DN14: =DM14/DI14*100 -> 11.755472 | DO14: 9.067003 | DP14: =IF(DT14>50,"**",IF(DT14>25,"*","")) | DQ14: 6.557725 | DR14: 12.40893 | DS14: 1.477404 | DT14: =DS14/DO14*100 -> 16.294293 | DU14: 3.495368 | DV14: =IF(DZ14>50,"**",IF(DZ14>25,"*","")) -> * | DW14: 1.977358 | DX14: 6.106153 | DY14: 1.007266 | DZ14: =DY14/DU14*100 -> 28.817166 | EA14: 4.554493 | EB14: =IF(EF14>50,"**",IF(EF14>25,"*","")) | EC14: 2.82928 | ED14: 7.253167 | EE14: 1.09563 | EF14: =EE14/EA14*100 -> 24.056026 | EG14: 5.017794 | EH14: =IF(EL14>50,"**",IF(EL14>25,"*","")) | EI14: 3.393045 | EJ14: 7.361266 | EK14: 0.9926352 | EL14: =EK14/EG14*100 -> 19.782303 | EM14: 0.8085241 | EN14: =IF(ER14>50,"**",IF(ER14>25,"*","")) -> * | EO14: 0.3628398 | EP14: 1.791808 | EQ14: 0.3296813 | ER14: =EQ14/EM14*100 -> 40.775692 | ES14: 18.31422 | ET14: =IF(EX14>50,"**",IF(EX14>25,"*","")) | EU14: 15.01223 | EV14: 22.15318 | EW14: 1.819912 | EX14: =EW14/ES14*100 -> 9.9371527 | EZ14: 54.72713 | FA14: =IF(FE14>50,"**",IF(FE14>25,"*","")) | FB14: 49.80762 | FC14: 59.55598 | FD14: 2.494633 | FE14: =FD14/EZ14*100 -> 4.5583114 | FF14: 82.0273 | FG14: =IF(FK14>50,"**",IF(FK14>25,"*","")) | FH14: 77.76137 | FI14: 85.62618 | FJ14: 2.003625 | FK14: =FJ14/FF14*100 -> 2.4426319 | FL14: 48.37544 | FM14: =IF(FQ14>50,"**",IF(FQ14>25,"*","")) | FN14: 43.39193 | FO14: 53.39149 | FP14: 2.559407 | FQ14: =FP14/FL14*100 -> 5.2907157 | FR14: 60.36994 | FS14: =IF(FW14>50,"**",IF(FW14>25,"*","")) | FT14: 51.2717 | FU14: 68.80306 | FV14: 4.51641 | FW14: =FV14/FR14*100 -> 7.4812233 | FX14: 56.96874 | FY14: =IF(GC14>50,"**",IF(GC14>25,"*","")) | FZ14: 48.97495 | GA14: 64.61502 | GB14: 4.022016 | GC14: =GB14/FX14*100 -> 7.0600403 | GD14: 89.94719 | GE14: =IF(GI14>50,"**",IF(GI14>25,"*","")) | GF14: 82.53673 | GG14: 94.42544 | GH14: 2.944042 | GI14: =GH14/GD14*100 -> 3.2730783 | GJ14: 13.36005 | GK14: =IF(GO14>50,"**",IF(GO14>25,"*","")) | GL14: 10.07724 | GM14: 17.5041 | GN14: 1.884937 | GO14: =GN14/GJ14*100 -> 14.108757
B15: Brimbank (C) | D15: 20.72741 | E15: =IF(I15>25,"*",IF(I15>50,"**","")) | F15: 16.76386 | G15: 25.34275 | H15: 2.188162 | I15: =H15/D15*100 -> 10.556852 | J15: 47.4744 | K15: =IF(O15>25,"*",IF(O15>50,"**","")) | L15: 42.23592 | M15: 52.76906 | N15: 2.696958 | O15: =N15/J15*100 -> 5.680868 | P15: 9.954818 | Q15: =IF(U15>50,"**",IF(U15>25,"*","")) | R15: 7.142204 | S15: 13.71149 | T15: 1.659162 | U15: =T15/P15*100 -> 16.666924 | V15: 18.8257 | W15: =IF(AA15>50,"**",IF(AA15>25,"*","")) | X15: 15.0439 | Y15: 23.29747 | Z15: 2.103416 | AA15: =Z15/V15*100 -> 11.173109 | AB15: 7.769267 | AC15: =IF(AG15>50,"**",IF(AG15>25,"*","")) | AD15: 4.95276 | AE15: 11.98548 | AF15: 1.755961 | AG15: =AF15/AB15*100 -> 22.601373 | AH15: 49.82556 | AI15: =IF(AM15>50,"**",IF(AM15>25,"*","")) | AJ15: 44.45055 | AK15: 55.2046 | AL15: 2.753981 | AM15: =AL15/AH15*100 -> 5.5272455 | AN15: 4.730466 | AO15: =IF(AS15>50,"**",IF(AS15>25,"*","")) | AP15: 2.947457 | AQ15: 7.508626 | AR15: 1.130386 | AS15: =AR15/AN15*100 -> 23.89587 | AT15: 41.47477 | AU15: =IF(AY15>50,"**",IF(AY15>25,"*","")) | AV15: 36.19925 | AW15: 46.95331 | AX15: 2.753645 | AY15: =AX15/AT15*100 -> 6.6393255 | AZ15: 16.36719 | BA15: =IF(BE15>50,"**",IF(BE15>25,"*","")) | BB15: 12.74623 | BC15: 20.77191 | BD15: 2.042237 | BE15: =BD15/AZ15*100 -> 12.477627 | BF15: 21.00059 | BG15: =IF(BK15>50,"**",IF(BK15>25,"*","")) | BH15: 16.87836 | BI15: 25.8169 | BJ15: 2.280139 | BK15: =BJ15/BF15*100 -> 10.8575 | BL15: 40.02309 | BM15: =IF(BQ15>50,"**",IF(BQ15>25,"*","")) | BN15: 34.7946 | BO15: 45.48915 | BP15: 2.738154 | BQ15: =BP15/BL15*100 -> 6.8414358 | BR15: 26.46095 | BS15: =IF(BW15>50,"**",IF(BW15>25,"*","")) | BT15: 21.863 | BU15: 31.63441 | BV15: 2.497098 | BW15: =BV15/BR15*100 -> 9.4369174 | BX15: 27.68898 | BY15: =IF(CC15>50,"**",IF(CC15>25,"*","")) | BZ15: 23.01001 | CA15: 32.91266 | CB15: 2.531374 | CC15: =CB15/BX15*100 -> 9.1421714 | CD15: 25.61678 | CE15: =IF(CI15>50,"**",IF(CI15>25,"*","")) | CF15: 21.16748 | CG15: 30.63782 | CH15: 2.419467 | CI15: =CH15/CD15*100 -> 9.4448522 | CJ15: 19.82 | CK15: =IF(CO15>50,"**",IF(CO15>25,"*","")) | CL15: 15.72 | CM15: 24.69 | CN15: 2.29 | CO15: =CN15/CJ15*100 -> 11.553986 | CP15: 28.93517 | CQ15: =IF(CU15>50,"**",IF(CU15>25,"*","")) | CR15: 24.97265 | CS15: 33.24782 | CT15: 2.114326 | CU15: =CT15/CP15*100 -> 7.3071145 | CW15: 27.74607 | CX15: =IF(DB15>50,"**",IF(DB15>25,"*","")) | CY15: 23.08235 | CZ15: 32.94844 | DA15: 2.522013 | DB15: =DA15/CW15*100 -> 9.0896224 | DC15: 20.82091 | DD15: =IF(DH15>50,"**",IF(DH15>25,"*","")) | DE15: 17.5584 | DF15: 24.5094 | DG15: 1.773061 | DH15: =DG15/DC15*100 -> 8.5157709 | DI15: 19.24106 | DJ15: =IF(DN15>50,"**",IF(DN15>25,"*","")) | DK15: 15.1958 | DL15: 24.05772 | DM15: 2.258679 | DN15: =DM15/DI15*100 -> 11.738849 | DO15: 6.252273 | DP15: =IF(DT15>50,"**",IF(DT15>25,"*","")) | DQ15: 4.327961 | DR15: 8.952119 | DS15: 1.16079 | DT15: =DS15/DO15*100 -> 18.565888 | DU15: 6.945853 | DV15: =IF(DZ15>50,"**",IF(DZ15>25,"*","")) | DW15: 4.970083 | DX15: 9.627483 | DY15: 1.173016 | DZ15: =DY15/DU15*100 -> 16.888005 | EA15: 8.239856 | EB15: =IF(EF15>50,"**",IF(EF15>25,"*","")) | EC15: 6.046907 | ED15: 11.13385 | EE15: 1.284766 | EF15: =EE15/EA15*100 -> 15.592093 | EG15: 6.317945 | EH15: =IF(EL15>50,"**",IF(EL15>25,"*","")) | EI15: 4.367223 | EJ15: 9.057477 | EK15: 1.17732 | EL15: =EK15/EG15*100 -> 18.63454 | EM15: 5.192812 | EN15: =IF(ER15>50,"**",IF(ER15>25,"*","")) | EO15: 3.376766 | EP15: 7.905628 | EQ15: 1.128617 | ER15: =EQ15/EM15*100 -> 21.734216 | ES15: 28.44738 | ET15: =IF(EX15>50,"**",IF(EX15>25,"*","")) | EU15: 24.00963 | EV15: 33.34544 | EW15: 2.386195 | EX15: =EW15/ES15*100 -> 8.3881011 | EZ15: 65.59353 | FA15: =IF(FE15>50,"**",IF(FE15>25,"*","")) | FB15: 60.84251 | FC15: 70.05184 | FD15: 2.355079 | FE15: =FD15/EZ15*100 -> 3.5904136 | FF15: 75.94039 | FG15: =IF(FK15>50,"**",IF(FK15>25,"*","")) | FH15: 71.3137 | FI15: 80.02983 | FJ15: 2.225527 | FK15: =FJ15/FF15*100 -> 2.9306236 | FL15: 61.59422 | FM15: =IF(FQ15>50,"**",IF(FQ15>25,"*","")) | FN15: 56.64643 | FO15: 66.31314 | FP15: 2.47319 | FQ15: =FP15/FL15*100 -> 4.0152956 | FR15: 61.83936 | FS15: =IF(FW15>50,"**",IF(FW15>25,"*","")) | FT15: 53.08148 | FU15: 69.88978 | FV15: 4.325924 | FW15: =FV15/FR15*100 -> 6.9954217 | FX15: 40.45022 | FY15: =IF(GC15>50,"**",IF(GC15>25,"*","")) | FZ15: 33.62719 | GA15: 47.66349 | GB15: 3.603397 | GC15: =GB15/FX15*100 -> 8.908226 | GD15: 74.40922 | GE15: =IF(GI15>50,"**",IF(GI15>25,"*","")) | GF15: 63.19311 | GG15: 83.12042 | GH15: 5.117771 | GI15: =GH15/GD15*100 -> 6.8778721 | GJ15: 20.66198 | GK15: =IF(GO15>50,"**",IF(GO15>25,"*","")) | GL15: 16.31588 | GM15: 25.80872 | GN15: 2.421141 | GO15: =GN15/GJ15*100 -> 11.717856
